Workbook

Sheet cronograma
A1: Nombre de la materia | B1: Analítica de Big Data
A2: Carrera | B2: =+_xlfn.XLOOKUP(B1,Tabla1[descrip],Tabla1[carrera],"",0,1) -> 09MED
A3: Modalidad | B3: Virtual
A4: Horas semanales de clase | B4: =+B5+B6 -> 4
A5: Horas teóricas | B5: 2
A6: Horas prácticas | B6: 2 | L6: =+WEEKDAY(L18) -> 6 | M6: =+WEEKDAY(M18) -> 7 | N6: =+WEEKDAY(N18) -> 1 | O6: =+WEEKDAY(O18) -> 2 | P6: =+WEEKDAY(P18) -> 3 | Q6: =+WEEKDAY(Q18) -> 4 | R6: =+WEEKDAY(R18) -> 5 | S6: =+WEEKDAY(S18) -> 6 | ... EV6: =+WEEKDAY(EV18) -> 6
A7: Año | B7: 2025
A8: Periodo | B8: 2
A9: Periodos | B9: Fecha inicio | C9: Fecha fin
A10: Periodo de clases 1ra etapa | B10: 45870 | C10: 45910
A11: Periodo de 1er parcial | B11: 45911 | C11: 45926
A12: Periodo de clases 2da etapa | B12: 45927 | C12: 45964
A13: Periodo de 2do parcial | B13: 45965 | C13: 45980
A14: Periodo finales | B14: 45981 | C14: 46018
A15: nombresyapellidos_profesor | B15: Diego Bernardo Meza Bogado | L15: =+IFERROR(WEEKDAY(L18),"") -> 6 | M15: =+IFERROR(WEEKDAY(M18),"") -> 7 | N15: =+IFERROR(WEEKDAY(N18),"") -> 1 | O15: =+IFERROR(WEEKDAY(O18),"") -> 2 | P15: =+IFERROR(WEEKDAY(P18),"") -> 3 | Q15: =+IFERROR(WEEKDAY(Q18),"") -> 4 | R15: =+IFERROR(WEEKDAY(R18),"") -> 5 | S15: =+IFERROR(WEEKDAY(S18),"") -> 6 | ... FQ15: =+IFERROR(WEEKDAY(FQ18),"")
A16: Resumen CV_profesor
A18: Unidad | B18: Nombre unidad | C18: Objetivo de la unidad | D18: Contenidos | E18: Descripcion de la actividad | F18: Tipo de actividad | G18: Puntaje asignado | H18: Objetivo de la actividad | I18: Duración (días) | J18: Fecha inicio | K18: Fecha fin | L18: =+B10 -> 45870 | M18: =IF(L18<$C$14,1+L18,"") -> 45871 | N18: =IF(M18<$C$14,1+M18,"") -> 45872 | O18: =IF(N18<$C$14,1+N18,"") -> 45873 | P18: =IF(O18<$C$14,1+O18,"") -> 45874 | Q18: =IF(P18<$C$14,1+P18,"") -> 45875 | R18: =IF(Q18<$C$14,1+Q18,"") -> 45876 | S18: =IF(R18<$C$14,1+R18,"") -> 45877 | T18: =IF(S18<$C$14,1+S18,"") -> 45878 | ... FQ18: =IF(FP18<$C$14,1+FP18,"")
A19: 1 | B19: Introducción al manejo de datos en Big Data | C19: Concocer los orígenes y principales caracteristicas del manejo de datos en BigData | D19: Orígen e Introducciones conceptuales a la Analítica de Big Data | E19: 1. Estudio de los materiales de aprendizaje | F19: AF | G19: 0 | I19: =+COUNTA(L19:FB19) -> 3 | J19: =+_xlfn.XLOOKUP(1,L19:FB19,$L$18:$FB$18,"",0,1) -> 45870 | K19: =+J19+I19-1 -> 45872 | L19: 1 | M19: 1 | N19: 1
A20: 1 | B20: Introducción al manejo de datos en Big Data | C20: Concocer los orígenes y principales caracteristicas del manejo de datos en BigData | D20: Instalación y configuración de R y Rstudio | E20: 2. Foro de discusión sobre problemas de aplicación | F20: AI | G20: 100 | I20: =+COUNTA(L20:FB20) -> 6 | J20: =+_xlfn.XLOOKUP(1,L20:FB20,$L$18:$FB$18,"",0,1) -> 45873 | K20: =+J20+I20-1 -> 45878 | O20: 1 | P20: 1 | Q20: 1 | R20: 1 | S20: 1 | T20: 1
A21: 1 | B21: Introducción al manejo de datos en Big Data | C21: Concocer los orígenes y principales caracteristicas del manejo de datos en BigData | D21: Operacione básicas y gráficos | E21: 3. Desarrollo del cuestionario en línea | F21: AA | G21: 100 | I21: =+COUNTA(L21:FB21) -> 6 | J21: =+_xlfn.XLOOKUP(1,L21:FB21,$L$18:$FB$18,"",0,1) -> 45879 | K21: =+J21+I21-1 -> 45884 | U21: 1 | V21: 1 | W21: 1 | X21: 1 | Y21: 1 | Z21: 1
A22: 2 | B22: Visualización y exploración de datos | C22: Comprender técnicas de visualización y análisis exploratorio. | D22: Librerías de R para big data, carga y procesamiento | E22: 1. Estudio de los materiales de aprendizaje | F22: AF | G22: 0 | I22: =+COUNTA(L22:FB22) -> 3 | J22: =+_xlfn.XLOOKUP(1,L22:FB22,$L$18:$FB$18,"",0,1) -> 45885 | K22: =+J22+I22-1 -> 45887 | AA22: 1 | AB22: 1 | AC22: 1
A23: 2 | B23: Visualización y exploración de datos | C23: Comprender técnicas de visualización y análisis exploratorio. | D23: Binarización de variables cualitativas. División de los datos en entrenamiento y test | E23: 2. Foro de discusión sobre problemas de aplicación | F23: AI | G23: 100 | I23: =+COUNTA(L23:FB23) -> 10 | J23: =+_xlfn.XLOOKUP(1,L23:FB23,$L$18:$FB$18,"",0,1) -> 45887 | K23: =+J23+I23-1 -> 45896 | AC23: 1 | AD23: 1 | AE23: 1 | AF23: 1 | AG23: 1 | AH23: 1 | AI23: 1 | AJ23: 1 | AK23: 1 | AL23: 1
A24: 2 | B24: Visualización y exploración de datos | C24: Comprender técnicas de visualización y análisis exploratorio. | D24: Técnicas de imputación, estandarización y escalado | E24: 3. Desarrollo del cuestionario en línea | F24: AA | G24: 100 | I24: =+COUNTA(L24:FB24) -> 13 | J24: =+_xlfn.XLOOKUP(1,L24:FB24,$L$18:$FB$18,"",0,1) -> 45897 | K24: =+J24+I24-1 -> 45909 | AM24: 1 | AN24: 1 | AO24: 1 | AP24: 1 | AQ24: 1 | AR24: 1 | AS24: 1 | AT24: 1 | AU24: 1 | AV24: 1 | AX24: 1 | AY24: 1 | AZ24: 1
A25: 3 | B25: Machine Learning | C25: Implementar modelos predictivos utilizando algoritmos de Machine Learning. | D25: Creación de modelo predictivo | E25: 1. Estudio de los materiales de aprendizaje | F25: AF | G25: 0 | I25: =+COUNTA(L25:FB25) -> 2 | J25: =+_xlfn.XLOOKUP(1,L25:FB25,$L$18:$FB$18,"",0,1) -> 45929 | K25: =+J25+I25-1 -> 45930 | BS25: 1 | BT25: 1
A26: 3 | B26: Machine Learning | C26: Implementar modelos predictivos utilizando algoritmos de Machine Learning. | D26: K-Nearest Neighbor (KNN) | E26: 2. Foro de discusión sobre problemas de aplicación | F26: AI | G26: 100 | I26: =+COUNTA(L26:FB26) -> 4 | J26: =+_xlfn.XLOOKUP(1,L26:FB26,$L$18:$FB$18,"",0,1) -> 45930 | K26: =+J26+I26-1 -> 45933 | BT26: 1 | BU26: 1 | BV26: 1 | BW26: 1
A27: 3 | B27: Machine Learning | C27: Implementar modelos predictivos utilizando algoritmos de Machine Learning. | D27: Regresión Logística | E27: 3. Desarrollo del cuestionario en línea | F27: AA | G27: 100 | I27: =+COUNTA(L27:FB27) -> 3 | J27: =+_xlfn.XLOOKUP(1,L27:FB27,$L$18:$FB$18,"",0,1) -> 45934 | K27: =+J27+I27-1 -> 45936 | BX27: 1 | BY27: 1 | BZ27: 1
A28: 4 | B28: Interpretación de los resultados y modelos estadísticos | C28: Analizar y comunicar resultados de modelos estadísticos aplicados a Big Data. | D28: Interpretación y selección de resultados y los modelos para generar información estadísticas en Big Data 1 | E28: 1. Estudio de los materiales de aprendizaje | F28: AI | G28: 0 | I28: =+COUNTA(L28:FB28) -> 5 | J28: =+_xlfn.XLOOKUP(1,L28:FB28,$L$18:$FB$18,"",0,1) -> 45937 | K28: =+J28+I28-1 -> 45941 | CA28: 1 | CB28: 1 | CC28: 1 | CD28: 1 | CE28: 1
A29: 4 | B29: Interpretación de los resultados y modelos estadísticos | C29: Analizar y comunicar resultados de modelos estadísticos aplicados a Big Data. | D29: Analisis Discriminante Lineal (LDA) | E29: 2. Foro de discusión sobre problemas de aplicación | F29: AA | G29: 100 | I29: =+COUNTA(L29:FB29) -> 4 | J29: =+_xlfn.XLOOKUP(1,L29:FB29,$L$18:$FB$18,"",0,1) -> 45942 | K29: =+J29+I29-1 -> 45945 | CF29: 1 | CG29: 1 | CH29: 1 | CI29: 1
A30: 4 | B30: Interpretación de los resultados y modelos estadísticos | C30: Analizar y comunicar resultados de modelos estadísticos aplicados a Big Data. | D30: Desarrollo de proyecto de investigación final | E30: 3. Desarrollo del cuestionario en línea | F30: AA | G30: 100 | I30: =+COUNTA(L30:FB30) -> 9 | J30: =+_xlfn.XLOOKUP(1,L30:FB30,$L$18:$FB$18,"",0,1) -> 45946 | K30: =+J30+I30-1 -> 45954 | CJ30: 1 | CK30: 1 | CL30: 1 | CM30: 1 | CN30: 1 | CO30: 1 | CP30: 1 | CQ30: 1 | CR30: 1
A31: 5 | B31: Evaluaciones parciales y Finales | C31: Integrar y aplicar los conocimientos adquiridos a través de un trabajo final. | D31: 1 | E31: Primer parcial | F31: AA | G31: 100 | I31: =+COUNTA(L31:FB31) -> 8 | J31: =+_xlfn.XLOOKUP(1,L31:FB31,$L$18:$FB$18,"",0,1) -> 45913 | K31: =+J31+I31-1 -> 45920 | BC31: 1 | CS31: 1 | CT31: 1 | CU31: 1 | CV31: 1 | CW31: 1 | CX31: 1 | CY31: 1
A32: 5 | B32: Evaluaciones parciales y Finales | C32: Integrar y aplicar los conocimientos adquiridos a través de un trabajo final. | D32: 2 | E32: Segundo parcial | F32: AA | G32: 100 | I32: =+COUNTA(L32:FB32) -> 1 | J32: =+_xlfn.XLOOKUP(1,L32:FB32,$L$18:$FB$18,"",0,1) -> 45968 | K32: =+J32+I32-1 -> 45968 | DF32: 1
A33: 5 | B33: Evaluaciones parciales y Finales | C33: Integrar y aplicar los conocimientos adquiridos a través de un trabajo final. | D33: 3 | E33: Primer final | F33: AA | G33: 100 | I33: =+COUNTA(L33:FB33) -> 1 | J33: =+_xlfn.XLOOKUP(1,L33:FB33,$L$18:$FB$18,"",0,1) -> 45987 | K33: =+J33+I33-1 -> 45987 | DY33: 1
A34: 5 | B34: Evaluaciones parciales y Finales | C34: Integrar y aplicar los conocimientos adquiridos a través de un trabajo final. | D34: 4 | E34: Segundo final | F34: AA | G34: 100 | I34: =+COUNTA(L34:FB34) -> 1 | J34: =+_xlfn.XLOOKUP(1,L34:FB34,$L$18:$FB$18,"",0,1) -> 46009 | K34: =+J34+I34-1 -> 46009 | EU34: 1
A35: 9 | B35: Tutoría sincrónica | C35: 1ra Tutoría sincrónica | D35: 1 | E35: Clase sincrónica | F35: AF | G35: 0 | I35: =+COUNTA(L35:FB35) -> 1 | J35: =+_xlfn.XLOOKUP(1,L35:FB35,$L$18:$FB$18,"",0,1) -> 45875 | K35: =+J35+I35-1 -> 45875 | Q35: 1
A36: 9 | B36: Tutoría sincrónica | C36: 2da Tutoría sincrónica | D36: 2 | E36: Clase sincrónica | F36: AF | G36: 0 | I36: =+COUNTA(L36:FB36) -> 1 | J36: =+_xlfn.XLOOKUP(1,L36:FB36,$L$18:$FB$18,"",0,1) -> 45882 | K36: =+J36+I36-1 -> 45882 | X36: 1
A37: 9 | B37: Tutoría sincrónica | C37: 3ra Tutoría sincrónica | D37: 3 | E37: Clase sincrónica | F37: AF | G37: 0 | I37: =+COUNTA(L37:FB37) -> 1 | J37: =+_xlfn.XLOOKUP(1,L37:FB37,$L$18:$FB$18,"",0,1) -> 45889 | K37: =+J37+I37-1 -> 45889 | AE37: 1
A38: 9 | B38: Tutoría sincrónica | C38: 4ta Tutoría sincrónica | D38: 4 | E38: Clase sincrónica | F38: AF | G38: 0 | I38: =+COUNTA(L38:FB38) -> 1 | J38: =+_xlfn.XLOOKUP(1,L38:FB38,$L$18:$FB$18,"",0,1) -> 45896 | K38: =+J38+I38-1 -> 45896 | AL38: 1
A39: 9 | B39: Tutoría sincrónica | C39: 5ta Tutoría sincrónica | D39: 5 | E39: Clase sincrónica | F39: AF | G39: 0 | I39: =+COUNTA(L39:FB39) -> 1 | J39: =+_xlfn.XLOOKUP(1,L39:FB39,$L$18:$FB$18,"",0,1) -> 45903 | K39: =+J39+I39-1 -> 45903 | AS39: 1
A40: 9 | B40: Tutoría sincrónica | C40: 6ta Tutoría sincrónica | D40: 6 | E40: Clase sincrónica | F40: AF | G40: 0 | I40: =+COUNTA(L40:FB40) -> 1 | J40: =+_xlfn.XLOOKUP(1,L40:FB40,$L$18:$FB$18,"",0,1) -> 45931 | K40: =+J40+I40-1 -> 45931 | BU40: 1
A41: 9 | B41: Tutoría sincrónica | C41: 7ma Tutoría sincrónica | D41: 7 | E41: Clase sincrónica | F41: AF | G41: 0 | I41: =+COUNTA(L41:FB41) -> 1 | J41: =+_xlfn.XLOOKUP(1,L41:FB41,$L$18:$FB$18,"",0,1) -> 45938 | K41: =+J41+I41-1 -> 45938 | CB41: 1
...

Sheet referencias
A1: Materia | B1: Unidad | C1: Descripción unidad | D1: Nombre de la unidad | E1: Nro. | F1: Desc actividad | G1: Objetivos | H1: ref2 | I1: ref3 | J1: Nro. Act. | K1: ref3
A2: =+cronograma!$B$1 -> Analítica de Big Data | B2: Unidad 1 | C2: En esta unidad vamos a abordar una introducción a los conceptos fundamentales que determinan el trabajo estadpistico con BigData y al manejo de este tipo de datos usando un software de licencia gratuita como R-project. Abordaremos situaciones como la instalación y configuraciones iniciales del programa, además de los comandos, operadores y funciones básicas | D2: Manejo de datos en Big Data – Introducciones conceptuales | E2: 1 | F2: Estudio de los materiales de aprendizaje de la unidad | G2: Identificar al menos uno de los programas informáticos que permiten encarar el análisis estadístico del Big Data | H2: =+_xlfn.CONCAT(Tabla5[[#This Row],[Unidad]],"-",Tabla5[[#This Row],[Nro.]]) -> Unidad 1-1 | I2: =+_xlfn.CONCAT(Tabla5[[#This Row],[Unidad]],"-",Tabla5[[#This Row],[Nro. Act.]]) -> Unidad 1-1 | J2: 1
A3: =+cronograma!$B$1 -> Analítica de Big Data | B3: Unidad 1 | C3: En esta unidad vamos a abordar una introducción a los conceptos fundamentales que determinan el trabajo estadpistico con BigData y al manejo de este tipo de datos usando un software de licencia gratuita como R-project. Abordaremos situaciones como la instalación y configuraciones iniciales del programa, además de los comandos, operadores y funciones básicas | D3: Manejo de datos en Big Data – Introducciones conceptuales | E3: 2 | F3: Foro de discusión sobre problemas de aplicación | G3: Identificar los pasos y las herramientas para realizar la recopilación y gestión de datos con las características particulares del Big Data | H3: =+_xlfn.CONCAT(Tabla5[[#This Row],[Unidad]],"-",Tabla5[[#This Row],[Nro.]]) -> Unidad 1-2 | I3: =+_xlfn.CONCAT(Tabla5[[#This Row],[Unidad]],"-",Tabla5[[#This Row],[Nro. Act.]]) -> Unidad 1-2 | J3: 2
A4: =+cronograma!$B$1 -> Analítica de Big Data | B4: Unidad 1 | C4: En esta unidad vamos a abordar una introducción a los conceptos fundamentales que determinan el trabajo estadpistico con BigData y al manejo de este tipo de datos usando un software de licencia gratuita como R-project. Abordaremos situaciones como la instalación y configuraciones iniciales del programa, además de los comandos, operadores y funciones básicas | D4: Manejo de datos en Big Data – Introducciones conceptuales | E4: 3 | F4: Desarrollo del cuestionario en línea de la unidad. | G4: Implementar códigos de programación para ejecutar rutinas relacionadas al tema de la unidad | H4: =+_xlfn.CONCAT(Tabla5[[#This Row],[Unidad]],"-",Tabla5[[#This Row],[Nro.]]) -> Unidad 1-3 | I4: =+_xlfn.CONCAT(Tabla5[[#This Row],[Unidad]],"-",Tabla5[[#This Row],[Nro. Act.]]) -> Unidad 1-3 | J4: 3
A5: =+cronograma!$B$1 -> Analítica de Big Data | B5: Unidad 2 | C5: En esta unidad vamos a iniciar la gestión y manejo de grandes volúmenes de datos para la lectura, corrección, imputación y preparado de las bases para el análisis estadístico, además de iniciar la exploración de los datos con el cálculo de estadísticas descriptivas y la utilización de gráficas | D5: Exploración y visualización datos en Big Data | E5: 1 | F5: Estudio de los materiales de aprendizaje de la unidad | G5: Emplear las técnicas adecuadas para visualizar y explorar el Big Data | H5: =+_xlfn.CONCAT(Tabla5[[#This Row],[Unidad]],"-",Tabla5[[#This Row],[Nro.]]) -> Unidad 2-1 | I5: =+_xlfn.CONCAT(Tabla5[[#This Row],[Unidad]],"-",Tabla5[[#This Row],[Nro. Act.]]) -> Unidad 2-1 | J5: 1
A6: =+cronograma!$B$1 -> Analítica de Big Data | B6: Unidad 2 | C6: En esta unidad vamos a iniciar la gestión y manejo de grandes volúmenes de datos para la lectura, corrección, imputación y preparado de las bases para el análisis estadístico, además de iniciar la exploración de los datos con el cálculo de estadísticas descriptivas y la utilización de gráficas | D6: Exploración y visualización datos en Big Data | E6: 2 | F6: Foro de discusión sobre problemas de aplicación | G6: Implementar códigos de programación para ejecutar rutinas relacionadas al tema de la unidad | H6: =+_xlfn.CONCAT(Tabla5[[#This Row],[Unidad]],"-",Tabla5[[#This Row],[Nro.]]) -> Unidad 2-2 | I6: =+_xlfn.CONCAT(Tabla5[[#This Row],[Unidad]],"-",Tabla5[[#This Row],[Nro. Act.]]) -> Unidad 2-2 | J6: 2
A7: =+cronograma!$B$1 -> Analítica de Big Data | B7: Unidad 2 | C7: En esta unidad vamos a iniciar la gestión y manejo de grandes volúmenes de datos para la lectura, corrección, imputación y preparado de las bases para el análisis estadístico, además de iniciar la exploración de los datos con el cálculo de estadísticas descriptivas y la utilización de gráficas | D7: Exploración y visualización datos en Big Data | E7: 3 | F7: Desarrollo del cuestionario en línea de la unidad. | H7: =+_xlfn.CONCAT(Tabla5[[#This Row],[Unidad]],"-",Tabla5[[#This Row],[Nro.]]) -> Unidad 2-3 | I7: =+_xlfn.CONCAT(Tabla5[[#This Row],[Unidad]],"-",Tabla5[[#This Row],[Nro. Act.]]) -> Unidad 2-3 | J7: 3
A8: =+cronograma!$B$1 -> Analítica de Big Data | B8: Unidad 3 | C8: En esta unidad vamos a abordar una introducción a las técnicas de aprendizaje automático o Machine Leanign mediante la creacion de modelos predictivos, la regresión logística, el análisis discriminante y otras técnicas estadísticas. | D8: Machine Learning para Big Data | E8: 1 | F8: Estudio de los materiales de aprendizaje de la unidad | G8: Identificar y utilizar algunas herramientas para la técnica de aprendizaje automático (Machine Learning) | H8: =+_xlfn.CONCAT(Tabla5[[#This Row],[Unidad]],"-",Tabla5[[#This Row],[Nro.]]) -> Unidad 3-1 | I8: =+_xlfn.CONCAT(Tabla5[[#This Row],[Unidad]],"-",Tabla5[[#This Row],[Nro. Act.]]) -> Unidad 3-1 | J8: 1
A9: =+cronograma!$B$1 -> Analítica de Big Data | B9: Unidad 3 | C9: En esta unidad vamos a abordar una introducción a las técnicas de aprendizaje automático o Machine Leanign mediante la creacion de modelos predictivos, la regresión logística, el análisis discriminante y otras técnicas estadísticas. | D9: Machine Learning para Big Data | E9: 2 | F9: Foro de discusión sobre problemas de aplicación | G9: Implementar códigos de programación para ejecutar rutinas relacionadas al tema de la unidad | H9: =+_xlfn.CONCAT(Tabla5[[#This Row],[Unidad]],"-",Tabla5[[#This Row],[Nro.]]) -> Unidad 3-2 | I9: =+_xlfn.CONCAT(Tabla5[[#This Row],[Unidad]],"-",Tabla5[[#This Row],[Nro. Act.]]) -> Unidad 3-2 | J9: 2
A10: =+cronograma!$B$1 -> Analítica de Big Data | B10: Unidad 3 | C10: En esta unidad vamos a abordar una introducción a las técnicas de aprendizaje automático o Machine Leanign mediante la creacion de modelos predictivos, la regresión logística, el análisis discriminante y otras técnicas estadísticas. | D10: Machine Learning para Big Data | E10: 3 | F10: Desarrollo del cuestionario en línea de la unidad. | H10: =+_xlfn.CONCAT(Tabla5[[#This Row],[Unidad]],"-",Tabla5[[#This Row],[Nro.]]) -> Unidad 3-3 | I10: =+_xlfn.CONCAT(Tabla5[[#This Row],[Unidad]],"-",Tabla5[[#This Row],[Nro. Act.]]) -> Unidad 3-3 | J10: 3
A11: =+cronograma!$B$1 -> Analítica de Big Data | B11: Unidad 4 | C11: En esta unidad vamos a estudiar la interpretación de los resultados y modelos estadísticos para generar información estadísticas en Big Data | D11: Interpretación de los resultados y modelos estadísticos en Big Data | E11: 1 | F11: Estudio de los materiales de aprendizaje de la unidad | G11: Describir e Interpretar los resultados obtenidos mediante la utilización de las técnicas para el modelado estadístico en Big Data | H11: =+_xlfn.CONCAT(Tabla5[[#This Row],[Unidad]],"-",Tabla5[[#This Row],[Nro.]]) -> Unidad 4-1 | I11: =+_xlfn.CONCAT(Tabla5[[#This Row],[Unidad]],"-",Tabla5[[#This Row],[Nro. Act.]]) -> Unidad 4-1 | J11: 1
A12: =+cronograma!$B$1 -> Analítica de Big Data | B12: Unidad 4 | C12: En esta unidad vamos a estudiar la interpretación de los resultados y modelos estadísticos para generar información estadísticas en Big Data | D12: Interpretación de los resultados y modelos estadísticos en Big Data | E12: 2 | F12: Foro de discusión sobre problemas de aplicación | G12: Implementar códigos de programación para ejecutar rutinas relacionadas al tema de la unidad | H12: =+_xlfn.CONCAT(Tabla5[[#This Row],[Unidad]],"-",Tabla5[[#This Row],[Nro.]]) -> Unidad 4-2 | I12: =+_xlfn.CONCAT(Tabla5[[#This Row],[Unidad]],"-",Tabla5[[#This Row],[Nro. Act.]]) -> Unidad 4-2 | J12: 2
A13: =+cronograma!$B$1 -> Analítica de Big Data | B13: Unidad 4 | C13: En esta unidad vamos a estudiar la interpretación de los resultados y modelos estadísticos para generar información estadísticas en Big Data | D13: Interpretación de los resultados y modelos estadísticos en Big Data | E13: 3 | F13: Desarrollo del cuestionario en línea de la unidad. | H13: =+_xlfn.CONCAT(Tabla5[[#This Row],[Unidad]],"-",Tabla5[[#This Row],[Nro.]]) -> Unidad 4-3 | I13: =+_xlfn.CONCAT(Tabla5[[#This Row],[Unidad]],"-",Tabla5[[#This Row],[Nro. Act.]]) -> Unidad 4-3 | J13: 3

Sheet GDcronog
B3: Analítica de Big Data
A4: 1 | B4: Cronograma de actividades
B6: Unidad | C6: Desc actividad | D6: Fecha inicio | E6: Fecha fin | F6: Tipo de activ. | G6: Puntaje asignado
A7: 1 | B7: Manejo de datos en Big Data – Introducciones conceptuales | C7: 1. Estudio de los materiales de aprendizaje de la unidad | D7: =+_xlfn.XLOOKUP(_xlfn.CONCAT("Unidad ",A7,"-",LEFT(C7,1)),cronograma!#REF!,cronograma!$J$19:$J$34,"",0,1) -> #REF! | E7: =+_xlfn.XLOOKUP(_xlfn.CONCAT("Unidad ",A7,"-",LEFT(C7,1)),cronograma!#REF!,cronograma!$K$19:$K$34,"",0,1) -> #REF! | F7: =++_xlfn.XLOOKUP(_xlfn.CONCAT("Unidad ",A7,"-",LEFT(C7,1)),cronograma!#REF!,cronograma!$F$19:$F$34,"",0,1) -> #REF! | G7: =+_xlfn.XLOOKUP(_xlfn.CONCAT("Unidad ",A7,"-",LEFT(C7,1)),cronograma!#REF!,cronograma!$G$19:$G$34,"",0,1) -> #REF!
A8: 1 | C8: 2. Foro de discusión sobre problemas de aplicación | D8: =+_xlfn.XLOOKUP(_xlfn.CONCAT("Unidad ",A8,"-",LEFT(C8,1)),cronograma!#REF!,cronograma!$J$19:$J$34,"",0,1) -> #REF! | E8: =+_xlfn.XLOOKUP(_xlfn.CONCAT("Unidad ",A8,"-",LEFT(C8,1)),cronograma!#REF!,cronograma!$K$19:$K$34,"",0,1) -> #REF! | F8: =++_xlfn.XLOOKUP(_xlfn.CONCAT("Unidad ",A8,"-",LEFT(C8,1)),cronograma!#REF!,cronograma!$F$19:$F$34,"",0,1) -> #REF! | G8: =+_xlfn.XLOOKUP(_xlfn.CONCAT("Unidad ",A8,"-",LEFT(C8,1)),cronograma!#REF!,cronograma!$G$19:$G$34,"",0,1) -> #REF!
A9: 1 | C9: 3. Desarrollo del cuestionario en línea de la unidad. | D9: =+_xlfn.XLOOKUP(_xlfn.CONCAT("Unidad ",A9,"-",LEFT(C9,1)),cronograma!#REF!,cronograma!$J$19:$J$34,"",0,1) -> #REF! | E9: =+_xlfn.XLOOKUP(_xlfn.CONCAT("Unidad ",A9,"-",LEFT(C9,1)),cronograma!#REF!,cronograma!$K$19:$K$34,"",0,1) -> #REF! | F9: =++_xlfn.XLOOKUP(_xlfn.CONCAT("Unidad ",A9,"-",LEFT(C9,1)),cronograma!#REF!,cronograma!$F$19:$F$34,"",0,1) -> #REF! | G9: =+_xlfn.XLOOKUP(_xlfn.CONCAT("Unidad ",A9,"-",LEFT(C9,1)),cronograma!#REF!,cronograma!$G$19:$G$34,"",0,1) -> #REF!
A10: 2 | B10: Exploración y visualización datos en Big Data | C10: 1. Estudio de los materiales de aprendizaje de la unidad | D10: =+_xlfn.XLOOKUP(_xlfn.CONCAT("Unidad ",A10,"-",LEFT(C10,1)),cronograma!#REF!,cronograma!$J$19:$J$34,"",0,1) -> #REF! | E10: =+_xlfn.XLOOKUP(_xlfn.CONCAT("Unidad ",A10,"-",LEFT(C10,1)),cronograma!#REF!,cronograma!$K$19:$K$34,"",0,1) -> #REF! | F10: =++_xlfn.XLOOKUP(_xlfn.CONCAT("Unidad ",A10,"-",LEFT(C10,1)),cronograma!#REF!,cronograma!$F$19:$F$34,"",0,1) -> #REF! | G10: =+_xlfn.XLOOKUP(_xlfn.CONCAT("Unidad ",A10,"-",LEFT(C10,1)),cronograma!#REF!,cronograma!$G$19:$G$34,"",0,1) -> #REF!
A11: 2 | C11: 2. Foro de discusión sobre problemas de aplicación | D11: =+_xlfn.XLOOKUP(_xlfn.CONCAT("Unidad ",A11,"-",LEFT(C11,1)),cronograma!#REF!,cronograma!$J$19:$J$34,"",0,1) -> #REF! | E11: =+_xlfn.XLOOKUP(_xlfn.CONCAT("Unidad ",A11,"-",LEFT(C11,1)),cronograma!#REF!,cronograma!$K$19:$K$34,"",0,1) -> #REF! | F11: =++_xlfn.XLOOKUP(_xlfn.CONCAT("Unidad ",A11,"-",LEFT(C11,1)),cronograma!#REF!,cronograma!$F$19:$F$34,"",0,1) -> #REF! | G11: =+_xlfn.XLOOKUP(_xlfn.CONCAT("Unidad ",A11,"-",LEFT(C11,1)),cronograma!#REF!,cronograma!$G$19:$G$34,"",0,1) -> #REF!
A12: 2 | C12: 3. Desarrollo del cuestionario en línea de la unidad. | D12: =+_xlfn.XLOOKUP(_xlfn.CONCAT("Unidad ",A12,"-",LEFT(C12,1)),cronograma!#REF!,cronograma!$J$19:$J$34,"",0,1) -> #REF! | E12: =+_xlfn.XLOOKUP(_xlfn.CONCAT("Unidad ",A12,"-",LEFT(C12,1)),cronograma!#REF!,cronograma!$K$19:$K$34,"",0,1) -> #REF! | F12: =++_xlfn.XLOOKUP(_xlfn.CONCAT("Unidad ",A12,"-",LEFT(C12,1)),cronograma!#REF!,cronograma!$F$19:$F$34,"",0,1) -> #REF! | G12: =+_xlfn.XLOOKUP(_xlfn.CONCAT("Unidad ",A12,"-",LEFT(C12,1)),cronograma!#REF!,cronograma!$G$19:$G$34,"",0,1) -> #REF!
A13: 3 | B13: Machine Learning para Big Data | C13: 1. Estudio de los materiales de aprendizaje de la unidad | D13: =+_xlfn.XLOOKUP(_xlfn.CONCAT("Unidad ",A13,"-",LEFT(C13,1)),cronograma!#REF!,cronograma!$J$19:$J$34,"",0,1) -> #REF! | E13: =+_xlfn.XLOOKUP(_xlfn.CONCAT("Unidad ",A13,"-",LEFT(C13,1)),cronograma!#REF!,cronograma!$K$19:$K$34,"",0,1) -> #REF! | F13: =++_xlfn.XLOOKUP(_xlfn.CONCAT("Unidad ",A13,"-",LEFT(C13,1)),cronograma!#REF!,cronograma!$F$19:$F$34,"",0,1) -> #REF! | G13: =+_xlfn.XLOOKUP(_xlfn.CONCAT("Unidad ",A13,"-",LEFT(C13,1)),cronograma!#REF!,cronograma!$G$19:$G$34,"",0,1) -> #REF!
A14: 3 | C14: 2. Foro de discusión sobre problemas de aplicación | D14: =+_xlfn.XLOOKUP(_xlfn.CONCAT("Unidad ",A14,"-",LEFT(C14,1)),cronograma!#REF!,cronograma!$J$19:$J$34,"",0,1) -> #REF! | E14: =+_xlfn.XLOOKUP(_xlfn.CONCAT("Unidad ",A14,"-",LEFT(C14,1)),cronograma!#REF!,cronograma!$K$19:$K$34,"",0,1) -> #REF! | F14: =++_xlfn.XLOOKUP(_xlfn.CONCAT("Unidad ",A14,"-",LEFT(C14,1)),cronograma!#REF!,cronograma!$F$19:$F$34,"",0,1) -> #REF! | G14: =+_xlfn.XLOOKUP(_xlfn.CONCAT("Unidad ",A14,"-",LEFT(C14,1)),cronograma!#REF!,cronograma!$G$19:$G$34,"",0,1) -> #REF!
A15: 3 | C15: 3. Desarrollo del cuestionario en línea de la unidad. | D15: =+_xlfn.XLOOKUP(_xlfn.CONCAT("Unidad ",A15,"-",LEFT(C15,1)),cronograma!#REF!,cronograma!$J$19:$J$34,"",0,1) -> #REF! | E15: =+_xlfn.XLOOKUP(_xlfn.CONCAT("Unidad ",A15,"-",LEFT(C15,1)),cronograma!#REF!,cronograma!$K$19:$K$34,"",0,1) -> #REF! | F15: =++_xlfn.XLOOKUP(_xlfn.CONCAT("Unidad ",A15,"-",LEFT(C15,1)),cronograma!#REF!,cronograma!$F$19:$F$34,"",0,1) -> #REF! | G15: =+_xlfn.XLOOKUP(_xlfn.CONCAT("Unidad ",A15,"-",LEFT(C15,1)),cronograma!#REF!,cronograma!$G$19:$G$34,"",0,1) -> #REF!
A16: 4 | B16: Interpretación de los resultados y modelos estadísticos en Big Data | C16: 1. Estudio de los materiales de aprendizaje de la unidad | D16: =+_xlfn.XLOOKUP(_xlfn.CONCAT("Unidad ",A16,"-",LEFT(C16,1)),cronograma!#REF!,cronograma!$J$19:$J$34,"",0,1) -> #REF! | E16: =+_xlfn.XLOOKUP(_xlfn.CONCAT("Unidad ",A16,"-",LEFT(C16,1)),cronograma!#REF!,cronograma!$K$19:$K$34,"",0,1) -> #REF! | F16: =++_xlfn.XLOOKUP(_xlfn.CONCAT("Unidad ",A16,"-",LEFT(C16,1)),cronograma!#REF!,cronograma!$F$19:$F$34,"",0,1) -> #REF! | G16: =+_xlfn.XLOOKUP(_xlfn.CONCAT("Unidad ",A16,"-",LEFT(C16,1)),cronograma!#REF!,cronograma!$G$19:$G$34,"",0,1) -> #REF!
A17: 4 | C17: 2. Foro de discusión sobre problemas de aplicación | D17: =+_xlfn.XLOOKUP(_xlfn.CONCAT("Unidad ",A17,"-",LEFT(C17,1)),cronograma!#REF!,cronograma!$J$19:$J$34,"",0,1) -> #REF! | E17: =+_xlfn.XLOOKUP(_xlfn.CONCAT("Unidad ",A17,"-",LEFT(C17,1)),cronograma!#REF!,cronograma!$K$19:$K$34,"",0,1) -> #REF! | F17: =++_xlfn.XLOOKUP(_xlfn.CONCAT("Unidad ",A17,"-",LEFT(C17,1)),cronograma!#REF!,cronograma!$F$19:$F$34,"",0,1) -> #REF! | G17: =+_xlfn.XLOOKUP(_xlfn.CONCAT("Unidad ",A17,"-",LEFT(C17,1)),cronograma!#REF!,cronograma!$G$19:$G$34,"",0,1) -> #REF!
A18: 4 | C18: 3. Desarrollo del cuestionario en línea de la unidad. | D18: =+_xlfn.XLOOKUP(_xlfn.CONCAT("Unidad ",A18,"-",LEFT(C18,1)),cronograma!#REF!,cronograma!$J$19:$J$34,"",0,1) -> #REF! | E18: =+_xlfn.XLOOKUP(_xlfn.CONCAT("Unidad ",A18,"-",LEFT(C18,1)),cronograma!#REF!,cronograma!$K$19:$K$34,"",0,1) -> #REF! | F18: =++_xlfn.XLOOKUP(_xlfn.CONCAT("Unidad ",A18,"-",LEFT(C18,1)),cronograma!#REF!,cronograma!$F$19:$F$34,"",0,1) -> #REF! | G18: =+_xlfn.XLOOKUP(_xlfn.CONCAT("Unidad ",A18,"-",LEFT(C18,1)),cronograma!#REF!,cronograma!$G$19:$G$34,"",0,1) -> #REF!
A19: 5 | B19: Clases sincrónicas | C19: 1ra Tutoría sincrónica | D19: =+_xlfn.XLOOKUP(C19,cronograma!$B$18:$B$44,cronograma!$J$18:$J$44,"",0,1) | E19: =+D19 | F19: AF | G19: 0
A20: 5 | C20: 2da Tutoría sincrónica | D20: =+_xlfn.XLOOKUP(C20,cronograma!$B$18:$B$44,cronograma!$J$18:$J$44,"",0,1) | E20: =+D20 | F20: AF | G20: 0
A21: 5 | C21: 3ra Tutoría sincrónica | D21: =+_xlfn.XLOOKUP(C21,cronograma!$B$18:$B$44,cronograma!$J$18:$J$44,"",0,1) | E21: =+D21 | F21: AF | G21: 0
A22: 5 | C22: 4ta Tutoría sincrónica | D22: =+_xlfn.XLOOKUP(C22,cronograma!$B$18:$B$44,cronograma!$J$18:$J$44,"",0,1) | E22: =+D22 | F22: AF | G22: 0
A23: 5 | C23: 5ta Tutoría sincrónica | D23: =+_xlfn.XLOOKUP(C23,cronograma!$B$18:$B$44,cronograma!$J$18:$J$44,"",0,1) | E23: =+D23 | F23: AF | G23: 0
A24: 5 | C24: 6ta Tutoría sincrónica | D24: =+_xlfn.XLOOKUP(C24,cronograma!$B$18:$B$44,cronograma!$J$18:$J$44,"",0,1) | E24: =+D24 | F24: AF | G24: 0
C25: 7ma Tutoría sincrónica | D25: =+_xlfn.XLOOKUP(C25,cronograma!$B$18:$B$44,cronograma!$J$18:$J$44,"",0,1) | E25: =+D25 | F25: AF | G25: 0
A26: 5 | C26: 8va Tutoría sincrónica | D26: =+_xlfn.XLOOKUP(C26,cronograma!$B$18:$B$44,cronograma!$J$18:$J$44,"",0,1) | E26: =+D26 | F26: AF | G26: 0
A27: 6 | B27: Evaluaciones | C27: 1. 1er parcial | D27: =+_xlfn.XLOOKUP(_xlfn.CONCAT("Unidad ",A27,"-",LEFT(C27,1)),cronograma!#REF!,cronograma!$J$19:$J$34,"",0,1) -> #REF! | E27: =+_xlfn.XLOOKUP(_xlfn.CONCAT("Unidad ",A27,"-",LEFT(C27,1)),cronograma!#REF!,cronograma!$K$19:$K$34,"",0,1) -> #REF! | F27: =++_xlfn.XLOOKUP(_xlfn.CONCAT("Unidad ",A27,"-",LEFT(C27,1)),cronograma!#REF!,cronograma!$F$19:$F$34,"",0,1) -> #REF! | G27: =+_xlfn.XLOOKUP(_xlfn.CONCAT("Unidad ",A27,"-",LEFT(C27,1)),cronograma!#REF!,cronograma!$G$19:$G$34,"",0,1) -> #REF!
A28: 6 | C28: 2. 2do parcial | D28: =+_xlfn.XLOOKUP(_xlfn.CONCAT("Unidad ",A28,"-",LEFT(C28,1)),cronograma!#REF!,cronograma!$J$19:$J$34,"",0,1) -> #REF! | E28: =+_xlfn.XLOOKUP(_xlfn.CONCAT("Unidad ",A28,"-",LEFT(C28,1)),cronograma!#REF!,cronograma!$K$19:$K$34,"",0,1) -> #REF! | F28: =++_xlfn.XLOOKUP(_xlfn.CONCAT("Unidad ",A28,"-",LEFT(C28,1)),cronograma!#REF!,cronograma!$F$19:$F$34,"",0,1) -> #REF! | G28: =+_xlfn.XLOOKUP(_xlfn.CONCAT("Unidad ",A28,"-",LEFT(C28,1)),cronograma!#REF!,cronograma!$G$19:$G$34,"",0,1) -> #REF!
A29: 6 | C29: 3. 1er final | D29: =+_xlfn.XLOOKUP(_xlfn.CONCAT("Unidad ",A29,"-",LEFT(C29,1)),cronograma!#REF!,cronograma!$J$19:$J$34,"",0,1) -> #REF! | E29: =+_xlfn.XLOOKUP(_xlfn.CONCAT("Unidad ",A29,"-",LEFT(C29,1)),cronograma!#REF!,cronograma!$K$19:$K$34,"",0,1) -> #REF! | F29: =++_xlfn.XLOOKUP(_xlfn.CONCAT("Unidad ",A29,"-",LEFT(C29,1)),cronograma!#REF!,cronograma!$F$19:$F$34,"",0,1) -> #REF! | G29: =+_xlfn.XLOOKUP(_xlfn.CONCAT("Unidad ",A29,"-",LEFT(C29,1)),cronograma!#REF!,cronograma!$G$19:$G$34,"",0,1) -> #REF!
A30: 6 | C30: 4. 2do final | D30: =+_xlfn.XLOOKUP(_xlfn.CONCAT("Unidad ",A30,"-",LEFT(C30,1)),cronograma!#REF!,cronograma!$J$19:$J$34,"",0,1) -> #REF! | E30: =+_xlfn.XLOOKUP(_xlfn.CONCAT("Unidad ",A30,"-",LEFT(C30,1)),cronograma!#REF!,cronograma!$K$19:$K$34,"",0,1) -> #REF! | F30: =++_xlfn.XLOOKUP(_xlfn.CONCAT("Unidad ",A30,"-",LEFT(C30,1)),cronograma!#REF!,cronograma!$F$19:$F$34,"",0,1) -> #REF! | G30: =+_xlfn.XLOOKUP(_xlfn.CONCAT("Unidad ",A30,"-",LEFT(C30,1)),cronograma!#REF!,cronograma!$G$19:$G$34,"",0,1) -> #REF!

Sheet GDportada
G15: Analítica de Big Data
G19: Guía Didáctica
I21: 2024

Sheet GDcuerpo
D41: Índice
D43: I. Identificación de la asignatura | AB43: 3
D44: II. Presentación del curso | AB44: 3
D45: III. Responsable del curso | AB45: 3
D46: IV. Objetivos | AB46: 4
D47: V. Metodología | AB47: 5
D48: VI. Contenido | AB48: 6
D49: VII. Cronograma | AB49: 7
D50: VIII. Actividades para el estudiante | AB50: 8
D51: IX. Asesoría de apoyo al aprendizaje de los estudiantes | AB51: 9
D52: X. Evaluación | AB52: 10
D53: XI. Recomendaciones y consideraciones finales | AB53: 10
D54: XII. Bibliografía | AB54: 11
Q71: 1
C80: I. Identificación de la asignatura
C82: 1. Código | K82: : 10C
C84: 2. Crédito | K84: : 3
C86: 3. Prerrequisitos | K86: : Álgebra
C88: II. Presentación del curso
C90: El Big Data es una forma de aplicar la ciencia de datos, específicamente cuando se requiere explorar grandes cantidades de datos que son generados continuamente y con gran velocidad al interior de las empresas o instituciones. Estos datos presentan características particulares que impiden su análisis con las técnicas tradicionales, y es así como surgen y evolucionan las nuevas técnicas, entre ellas las conocidas como Analítica de Big Data. Estas técnicas proporcionan una manera de acceder, gestionar y analizar estos datos atendiendo sus particularidades, de modo a encontrar patrones, relaciones y verificar algunas presunciones al respecto de ellas. Atendiendo al vertiginoso ritmo en la generación de datos que las tecnologías actuales permiten a las empresas e instituciones, y la interrelación entre ellas, resulta necesario y sumamente importante el desarrollo de este curso, de modo a apoyar el aprendizaje en las técnicas en ciencias de datos que dan respuesta a las tendencias y las necesidades que surgen en la gestión de información, debido a estos cambios y avances tecnológicos. Fortaleciendo y fomentando de esta manera nuevos campos de investigación dentro y fuera de la universidad, además de proporcionar a los egresados las herramientas básicas que les permitirán encarar los verdaderos desafíos que encontrarán al momento de incorporarse en el mundo de trabajo relacionado a la estadística y la ciencia de datos.
C115: III. Objetivos
C117: Objetivo General
C118: Otorgar a los participantes conocimientos para la gestión y el análisis estadístico de grandes volúmenes de datos o BIG DATA, mediante las herramientas brindadas por el software open sourse como R.
C123: Objetivos Específicos
C125: 1. dentificar algunos de los programas informáticos que permiten encarar el análisis estadístico del Big Data. 2. Identificar los pasos y las herramientas para realizar la recopilación y gestión de datos con las características particulares del Big Data. 3.Emplear las técnicas adecuadas para visualizar y explorar el Big Data 4. Identificar y utilizar algunas herramientas para la técnica de aprendizaje automático (Machine Learning) 5. Describir e Interpretar los resultados obtenidos mediante la utilización de las técnicas para el modelado estadístico en Big Data.
C153: IV. Metodología La asignatura se desarrollará en la modalidad semipresencial, la cual implica la combinación de actividades presenciales, tales como los encuentros con el tutor y los exámenes finales, y no presenciales a través de la plataforma virtual Moodle. Se utilizarán las herramientas ofrecidas por la plataforma: foros, cuestionarios, tareas, etc. Las tutorías serán virtuales como presenciales. El ingreso a la plataforma se realiza con el usuario y contraseña que tendrá cada estudiante. Se puede ingresar a la plataforma desde cualquier computadora con acceso a Internet, para lo cual se recomienda utilizar el navegador Mozilla Firefox. Las unidades de la asignatura se habilitarán gradualmente y, al inicio de cada una, se encontrará una bienvenida y los detalles de los pasos a seguir para el cumplimiento de los objetivos. Cada unidad tendrá Orientaciones donde estará de forma detallada todo lo que se desarrollará en la misma. Además, en dichas orientaciones se especificarán las actividades y los plazos para la realización de estas. Para poder cumplir con todo lo planificado para este semestre, es responsabilidad de cada estudiante ingresar por lo menos cada dos días y tomar nota de las novedades, las asignaciones que debe realizar y los plazos máximos de entrega de las distintas tareas. El tutor virtual estará guiando constantemente los trabajos individuales y grupales para la profundización de los nuevos conceptos aprendidos, apoyando a los estudiantes en el uso de la plataforma y respondiendo a las consultas que se consideren necesarias, además de retroalimentar constantemente a los participantes sobre sus avances y dar recomendaciones acordes a lo que la situación requiera.
B191: V. Contenidos Unidad 1: Manejo de datos en Big Data – Introducciones conceptuales 1. Definición de Big Data 2. Principales características 3. Importancia en la era digital 4. Ejemplos prácticos de aplicación de Big Data 5. Casos de estudio en diversas industrias 6. Soluciones innovadoras a través de Big Data Unidad 2: Visualización y exploración de datos con R 1. Binarización de variables cualitativas 2. Selección de predictores 3. Tipo de variables y distribución 4. Distribución de variables de respuesta discreta 5. Exploración de datos 6. División de los datos en entrenamiento y test 7. Preprocesado de los datos 8. Imputación de valores ausentes 9. Variables con varianza a cero 10. Estandarización y escalado 11. Árbol de clasificación simple 12. Random Forest Unidad 3: Machine Learning con R 1. Creación de modelo predictivo 2. K-Nearest Neighbor (KNN) 3. Naive Bayes 4. Regresión Logística Unidad 4: Interpretación de los resultados y modelos estadísticos obtenidos con R 1. Análisis Discriminante Lineal (LDA) 2. Support Vector Machine 3. Redes Neuronales (NNET) 4. Gradient Boosting 5. Interpretación y selección de resultados y los modelos para generar información estadística en Big Data
B226: V. Cronograma
C228: Unidad | H228: Desc actividad | Q228: Fecha inicio | T228: Fecha fin | W228: Tipo de activ. | Z228: Puntos
A229: 1 | C229: Manejo de datos en Big Data – Introducciones conceptuales | H229: 1. Estudio de los materiales de aprendizaje de la unidad | Q229: 45355 | T229: 45357 | W229: AF | Z229: 0
A230: 1 | H230: 2. Foro de discusión sobre problemas de aplicación | Q230: 45358 | T230: 45362 | W230: AA | Z230: 100
A231: 1 | H231: 3. Desarrollo del cuestionario en línea de la unidad. | Q231: 45364 | T231: 45367 | W231: AA | Z231: 100
A232: 2 | C232: Exploración y visualización datos en Big Data | H232: 1. Estudio de los materiales de aprendizaje de la unidad | Q232: 45369 | T232: 45372 | W232: AF | Z232: 0
A233: 2 | H233: 2. Foro de discusión sobre problemas de aplicación | Q233: 45372 | T233: 45380 | W233: AA | Z233: 100
A234: 2 | H234: 3. Desarrollo del cuestionario en línea de la unidad. | Q234: 45383 | T234: 45389 | W234: AA | Z234: 100
A235: 3 | C235: Machine Learning para Big Data | H235: 1. Estudio de los materiales de aprendizaje de la unidad | Q235: 45408 | T235: 45411 | W235: AF | Z235: 0
A236: 3 | H236: 2. Foro de discusión sobre problemas de aplicación | Q236: 45413 | T236: 45416 | W236: AA | Z236: 100
A237: 3 | H237: 3. Desarrollo del cuestionario en línea de la unidad. | Q237: 45418 | T237: 45423 | W237: AA | Z237: 100
A238: 4 | C238: Interpretación de los resultados y modelos estadísticos en Big Data | H238: 1. Estudio de los materiales de aprendizaje de la unidad | Q238: 45425 | T238: 45428 | W238: AF | Z238: 0
A239: 4 | H239: 2. Foro de discusión sobre problemas de aplicación | Q239: 45429 | T239: 45436 | W239: AA | Z239: 100
...

Sheet OU1
B3: Analítica de Big Data
A4: 1 | B4: =+_xlfn.CONCAT("Unidad ",A4,": ",_xlfn.XLOOKUP(_xlfn.CONCAT("Unidad ",A4),Tabla5[Unidad],Tabla5[Nombre de la unidad],"",0,1)) -> Unidad 1: Manejo de datos en Big Data – Introducciones conceptuales
B5: Orientaciones de la unidad
B6: =+_xlfn.XLOOKUP(_xlfn.CONCAT("Unidad ",$A$4),referencias!B2:B13,referencias!C2:C13,"",0,1) -> En esta unidad vamos a abordar una introducción a los conceptos fundamentales que determinan el trabajo estadpistico con BigData y al manejo de este tipo de datos usando un software de licencia gratuita como R-project. Abordaremos situaciones como la instalación y configuraciones iniciales del programa, además de los comandos, operadores y funciones básicas
B10: Se espera que al culminar esta unidad logres:
B12: Nro. | C12: Objetivos
B13: 1 | C13: {=+_xlfn.XLOOKUP(_xlfn.CONCAT("Unidad ",$A$4,"-",B13),Tabla5[ref3],referencias!$G$2:$G$13,"",0,1)} -> Identificar al menos uno de los programas informáticos que permiten encarar el análisis estadístico del Big Data
B14: 2 | C14: {=+_xlfn.XLOOKUP(_xlfn.CONCAT("Unidad ",$A$4,"-",B14),Tabla5[ref3],referencias!$G$2:$G$13,"",0,1)} -> Identificar los pasos y las herramientas para realizar la recopilación y gestión de datos con las características particulares del Big Data
B15: 3 | C15: {=+_xlfn.XLOOKUP(_xlfn.CONCAT("Unidad ",$A$4,"-",B15),Tabla5[ref3],referencias!$G$2:$G$13,"",0,1)} -> Implementar códigos de programación para ejecutar rutinas relacionadas al tema de la unidad
B17: Las actividades que se realizarán para el logro de estos objetivos son:
B19: Nro. | C19: Descripción de Actividad | D19: Inicio | E19: Fin | F19: Puntos
B20: 1 | C20: Estudio de los materiales de aprendizaje de la unidad (AF) | D20: =+_xlfn.XLOOKUP(_xlfn.CONCAT("Unidad ",$A$4,"-",B20),cronograma!#REF!,cronograma!$J$19:$J$34,"-",0,1) -> #REF! | E20: =+_xlfn.XLOOKUP(_xlfn.CONCAT("Unidad ",$A$4,"-",B20),cronograma!#REF!,cronograma!$K$19:$K$34,"-",0,1) -> #REF! | F20: 0
B21: 2 | C21: Foro de discusión sobre problemas de aplicación (AI) | D21: =+_xlfn.XLOOKUP(_xlfn.CONCAT("Unidad ",$A$4,"-",B21),cronograma!#REF!,cronograma!$J$19:$J$34,"-",0,1) -> #REF! | E21: =+_xlfn.XLOOKUP(_xlfn.CONCAT("Unidad ",$A$4,"-",B21),cronograma!#REF!,cronograma!$K$19:$K$34,"-",0,1) -> #REF! | F21: 100
B22: 3 | C22: Desarrollo del cuestionario en línea de la unidad. (AA) | D22: =+_xlfn.XLOOKUP(_xlfn.CONCAT("Unidad ",$A$4,"-",B22),cronograma!#REF!,cronograma!$J$19:$J$34,"-",0,1) -> #REF! | E22: =+_xlfn.XLOOKUP(_xlfn.CONCAT("Unidad ",$A$4,"-",B22),cronograma!#REF!,cronograma!$K$19:$K$34,"-",0,1) -> #REF! | F22: 100
B23: 6 | C23: =+IF(D23="-","","Clase sincrónica de la unidad (2da) (AF)") -> #REF! | D23: =+_xlfn.XLOOKUP(_xlfn.CONCAT("Unidad ",$A$4,"-",B23),cronograma!#REF!,cronograma!$J$19:$J$34,"-",0,1) -> #REF! | E23: =+_xlfn.XLOOKUP(_xlfn.CONCAT("Unidad ",$A$4,"-",B23),cronograma!#REF!,cronograma!$K$19:$K$34,"-",0,1) -> #REF! | F23: 0
B24: 7 | C24: =+IF(D24="-","","Clase sincrónica de la unidad (3ra) (AF)") -> #REF! | D24: =+_xlfn.XLOOKUP(_xlfn.CONCAT("Unidad ",$A$4,"-",B24),cronograma!#REF!,cronograma!$J$19:$J$34,"-",0,1) -> #REF! | E24: =+_xlfn.XLOOKUP(_xlfn.CONCAT("Unidad ",$A$4,"-",B24),cronograma!#REF!,cronograma!$K$19:$K$34,"-",0,1) -> #REF!
B26: Referencias: AA: Actividad de aprendizaje individual AI: Actividad Interactiva AF: Actividad de Fijación Estas fechas son recomendaciones para ayudar a la organización de tus estudios. Principalmente, debes tener en cuenta las fechas de entrega y los periodos de participación de las actividades. Ante cualquier duda, recuerda que puedes manifestarla en el foro Consultas de esta unidad. Estoy aquí para acompañarte.

Sheet OU2
B3: Analítica de Big Data
A4: 2 | B4: =+_xlfn.CONCAT("Unidad ",A4,": ",_xlfn.XLOOKUP(_xlfn.CONCAT("Unidad ",A4),Tabla5[Unidad],Tabla5[Nombre de la unidad],"",0,1)) -> Unidad 2: Exploración y visualización datos en Big Data
B5: Orientaciones de la unidad
B6: =+_xlfn.XLOOKUP(_xlfn.CONCAT("Unidad ",$A$4),referencias!B2:B13,referencias!C2:C13,"",0,1) -> En esta unidad vamos a iniciar la gestión y manejo de grandes volúmenes de datos para la lectura, corrección, imputación y preparado de las bases para el análisis estadístico, además de iniciar la exploración de los datos con el cálculo de estadísticas descriptivas y la utilización de gráficas
B10: Se espera que al culminar esta unidad logres:
B12: Nro. | C12: Objetivos
B13: 1 | C13: {=+_xlfn.XLOOKUP(_xlfn.CONCAT("Unidad ",$A$4,"-",B13),Tabla5[ref3],referencias!$G$2:$G$13,"",0,1)} -> Emplear las técnicas adecuadas para visualizar y explorar el Big Data
B14: 2 | C14: {=+_xlfn.XLOOKUP(_xlfn.CONCAT("Unidad ",$A$4,"-",B14),Tabla5[ref3],referencias!$G$2:$G$13,"",0,1)} -> Implementar códigos de programación para ejecutar rutinas relacionadas al tema de la unidad
B15: 3 | C15: {=+_xlfn.XLOOKUP(_xlfn.CONCAT("Unidad ",$A$4,"-",B15),Tabla5[ref3],referencias!$G$2:$G$13,"",0,1)} -> 0
B17: Las actividades que se realizarán para el logro de estos objetivos son:
B19: Nro. | C19: Descripción de Actividad | D19: Inicio | E19: Fin | F19: Puntos
B20: 1 | C20: Estudio de los materiales de aprendizaje de la unidad (AF) | D20: =+_xlfn.XLOOKUP(_xlfn.CONCAT("Unidad ",$A$4,"-",B20),cronograma!#REF!,cronograma!$J$19:$J$34,"-",0,1) -> #REF! | E20: =+_xlfn.XLOOKUP(_xlfn.CONCAT("Unidad ",$A$4,"-",B20),cronograma!#REF!,cronograma!$K$19:$K$34,"-",0,1) -> #REF! | F20: 0
B21: 2 | C21: Foro de discusión sobre problemas de aplicación (AI) | D21: =+_xlfn.XLOOKUP(_xlfn.CONCAT("Unidad ",$A$4,"-",B21),cronograma!#REF!,cronograma!$J$19:$J$34,"-",0,1) -> #REF! | E21: =+_xlfn.XLOOKUP(_xlfn.CONCAT("Unidad ",$A$4,"-",B21),cronograma!#REF!,cronograma!$K$19:$K$34,"-",0,1) -> #REF! | F21: 100
B22: 3 | C22: Desarrollo del cuestionario en línea de la unidad. (AA) | D22: =+_xlfn.XLOOKUP(_xlfn.CONCAT("Unidad ",$A$4,"-",B22),cronograma!#REF!,cronograma!$J$19:$J$34,"-",0,1) -> #REF! | E22: =+_xlfn.XLOOKUP(_xlfn.CONCAT("Unidad ",$A$4,"-",B22),cronograma!#REF!,cronograma!$K$19:$K$34,"-",0,1) -> #REF! | F22: 100
B23: 6 | C23: =+IF(D23="-","","Clase sincrónica de la unidad (2da) (AF)") -> #REF! | D23: =+_xlfn.XLOOKUP(_xlfn.CONCAT("Unidad ",$A$4,"-",B23),cronograma!#REF!,cronograma!$J$19:$J$34,"-",0,1) -> #REF! | E23: =+_xlfn.XLOOKUP(_xlfn.CONCAT("Unidad ",$A$4,"-",B23),cronograma!#REF!,cronograma!$K$19:$K$34,"-",0,1) -> #REF! | F23: 0
B24: 7 | C24: =+IF(D24="-","","Clase sincrónica de la unidad (3ra) (AF)") -> #REF! | D24: =+_xlfn.XLOOKUP(_xlfn.CONCAT("Unidad ",$A$4,"-",B24),cronograma!#REF!,cronograma!$J$19:$J$34,"-",0,1) -> #REF! | E24: =+_xlfn.XLOOKUP(_xlfn.CONCAT("Unidad ",$A$4,"-",B24),cronograma!#REF!,cronograma!$K$19:$K$34,"-",0,1) -> #REF!
B26: Referencias: AA: Actividad de aprendizaje individual AI: Actividad Interactiva AF: Actividad de Fijación Estas fechas son recomendaciones para ayudar a la organización de tus estudios. Principalmente, debes tener en cuenta las fechas de entrega y los periodos de participación de las actividades. Ante cualquier duda, recuerda que puedes manifestarla en el foro Consultas de esta unidad. Estoy aquí para acompañarte.

Sheet OU3
B3: Analítica de Big Data
A4: 3 | B4: =+_xlfn.CONCAT("Unidad ",A4,": ",_xlfn.XLOOKUP(_xlfn.CONCAT("Unidad ",A4),Tabla5[Unidad],Tabla5[Nombre de la unidad],"",0,1)) -> Unidad 3: Machine Learning para Big Data
B5: Orientaciones de la unidad
B6: =+_xlfn.XLOOKUP(_xlfn.CONCAT("Unidad ",$A$4),referencias!B2:B13,referencias!C2:C13,"",0,1) -> En esta unidad vamos a abordar una introducción a las técnicas de aprendizaje automático o Machine Leanign mediante la creacion de modelos predictivos, la regresión logística, el análisis discriminante y otras técnicas estadísticas.
B10: Se espera que al culminar esta unidad logres:
B12: Nro. | C12: Objetivos
B13: 1 | C13: {=+_xlfn.XLOOKUP(_xlfn.CONCAT("Unidad ",$A$4,"-",B13),Tabla5[ref3],referencias!$G$2:$G$13,"",0,1)} -> Identificar y utilizar algunas herramientas para la técnica de aprendizaje automático (Machine Learning)
B14: 2 | C14: {=+_xlfn.XLOOKUP(_xlfn.CONCAT("Unidad ",$A$4,"-",B14),Tabla5[ref3],referencias!$G$2:$G$13,"",0,1)} -> Implementar códigos de programación para ejecutar rutinas relacionadas al tema de la unidad
B15: 3 | C15: {=+_xlfn.XLOOKUP(_xlfn.CONCAT("Unidad ",$A$4,"-",B15),Tabla5[ref3],referencias!$G$2:$G$13,"",0,1)} -> 0
B17: Las actividades que se realizarán para el logro de estos objetivos son:
B19: Nro. | C19: Descripción de Actividad | D19: Inicio | E19: Fin | F19: Puntos
B20: 1 | C20: Estudio de los materiales de aprendizaje de la unidad (AF) | D20: =+_xlfn.XLOOKUP(_xlfn.CONCAT("Unidad ",$A$4,"-",B20),cronograma!#REF!,cronograma!$J$19:$J$34,"-",0,1) -> #REF! | E20: =+_xlfn.XLOOKUP(_xlfn.CONCAT("Unidad ",$A$4,"-",B20),cronograma!#REF!,cronograma!$K$19:$K$34,"-",0,1) -> #REF! | F20: 0
B21: 2 | C21: Foro de discusión sobre problemas de aplicación (AI) | D21: =+_xlfn.XLOOKUP(_xlfn.CONCAT("Unidad ",$A$4,"-",B21),cronograma!#REF!,cronograma!$J$19:$J$34,"-",0,1) -> #REF! | E21: =+_xlfn.XLOOKUP(_xlfn.CONCAT("Unidad ",$A$4,"-",B21),cronograma!#REF!,cronograma!$K$19:$K$34,"-",0,1) -> #REF! | F21: 100
B22: 3 | C22: Desarrollo del cuestionario en línea de la unidad. (AA) | D22: =+_xlfn.XLOOKUP(_xlfn.CONCAT("Unidad ",$A$4,"-",B22),cronograma!#REF!,cronograma!$J$19:$J$34,"-",0,1) -> #REF! | E22: =+_xlfn.XLOOKUP(_xlfn.CONCAT("Unidad ",$A$4,"-",B22),cronograma!#REF!,cronograma!$K$19:$K$34,"-",0,1) -> #REF! | F22: 100
B23: 6 | C23: =+IF(D23="-","","Clase sincrónica de la unidad (2da) (AF)") -> #REF! | D23: =+_xlfn.XLOOKUP(_xlfn.CONCAT("Unidad ",$A$4,"-",B23),cronograma!#REF!,cronograma!$J$19:$J$34,"-",0,1) -> #REF! | E23: =+_xlfn.XLOOKUP(_xlfn.CONCAT("Unidad ",$A$4,"-",B23),cronograma!#REF!,cronograma!$K$19:$K$34,"-",0,1) -> #REF! | F23: 0
B24: 7 | C24: =+IF(D24="-","","Clase sincrónica de la unidad (3ra) (AF)") -> #REF! | D24: =+_xlfn.XLOOKUP(_xlfn.CONCAT("Unidad ",$A$4,"-",B24),cronograma!#REF!,cronograma!$J$19:$J$34,"-",0,1) -> #REF! | E24: =+_xlfn.XLOOKUP(_xlfn.CONCAT("Unidad ",$A$4,"-",B24),cronograma!#REF!,cronograma!$K$19:$K$34,"-",0,1) -> #REF!
B26: Referencias: AA: Actividad de aprendizaje individual AI: Actividad Interactiva AF: Actividad de Fijación Estas fechas son recomendaciones para ayudar a la organización de tus estudios. Principalmente, debes tener en cuenta las fechas de entrega y los periodos de participación de las actividades. Ante cualquier duda, recuerda que puedes manifestarla en el foro Consultas de esta unidad. Estoy aquí para acompañarte.

Sheet OU4
B3: Analítica de Big Data
A4: 4 | B4: =+_xlfn.CONCAT("Unidad ",A4,": ",_xlfn.XLOOKUP(_xlfn.CONCAT("Unidad ",A4),Tabla5[Unidad],Tabla5[Nombre de la unidad],"",0,1)) -> Unidad 4: Interpretación de los resultados y modelos estadísticos en Big Data
B5: Orientaciones de la unidad
B6: =+_xlfn.XLOOKUP(_xlfn.CONCAT("Unidad ",$A$4),referencias!B2:B13,referencias!C2:C13,"",0,1) -> En esta unidad vamos a estudiar la interpretación de los resultados y modelos estadísticos para generar información estadísticas en Big Data
B10: Se espera que al culminar esta unidad logres:
B12: Nro. | C12: Objetivos
B13: 1 | C13: {=+_xlfn.XLOOKUP(_xlfn.CONCAT("Unidad ",$A$4,"-",B13),Tabla5[ref3],referencias!$G$2:$G$13,"",0,1)} -> Describir e Interpretar los resultados obtenidos mediante la utilización de las técnicas para el modelado estadístico en Big Data
B14: 2 | C14: {=+_xlfn.XLOOKUP(_xlfn.CONCAT("Unidad ",$A$4,"-",B14),Tabla5[ref3],referencias!$G$2:$G$13,"",0,1)} -> Implementar códigos de programación para ejecutar rutinas relacionadas al tema de la unidad
B15: 3 | C15: {=+_xlfn.XLOOKUP(_xlfn.CONCAT("Unidad ",$A$4,"-",B15),Tabla5[ref3],referencias!$G$2:$G$13,"",0,1)} -> 0
B17: Las actividades que se realizarán para el logro de estos objetivos son:
B19: Nro. | C19: Descripción de Actividad | D19: Inicio | E19: Fin | F19: Puntos
B20: 1 | C20: Estudio de los materiales de aprendizaje de la unidad (AF) | D20: =+_xlfn.XLOOKUP(_xlfn.CONCAT("Unidad ",$A$4,"-",B20),cronograma!#REF!,cronograma!$J$19:$J$34,"-",0,1) -> #REF! | E20: =+_xlfn.XLOOKUP(_xlfn.CONCAT("Unidad ",$A$4,"-",B20),cronograma!#REF!,cronograma!$K$19:$K$34,"-",0,1) -> #REF! | F20: 0
B21: 2 | C21: Foro de discusión sobre problemas de aplicación (AI) | D21: =+_xlfn.XLOOKUP(_xlfn.CONCAT("Unidad ",$A$4,"-",B21),cronograma!#REF!,cronograma!$J$19:$J$34,"-",0,1) -> #REF! | E21: =+_xlfn.XLOOKUP(_xlfn.CONCAT("Unidad ",$A$4,"-",B21),cronograma!#REF!,cronograma!$K$19:$K$34,"-",0,1) -> #REF! | F21: 100
B22: 3 | C22: Desarrollo del cuestionario en línea de la unidad. (AA) | D22: =+_xlfn.XLOOKUP(_xlfn.CONCAT("Unidad ",$A$4,"-",B22),cronograma!#REF!,cronograma!$J$19:$J$34,"-",0,1) -> #REF! | E22: =+_xlfn.XLOOKUP(_xlfn.CONCAT("Unidad ",$A$4,"-",B22),cronograma!#REF!,cronograma!$K$19:$K$34,"-",0,1) -> #REF! | F22: 100
B23: 6 | C23: =+IF(D23="-","","Clase sincrónica de la unidad (2da) (AF)") -> #REF! | D23: =+_xlfn.XLOOKUP(_xlfn.CONCAT("Unidad ",$A$4,"-",B23),cronograma!#REF!,cronograma!$J$19:$J$34,"-",0,1) -> #REF! | E23: =+_xlfn.XLOOKUP(_xlfn.CONCAT("Unidad ",$A$4,"-",B23),cronograma!#REF!,cronograma!$K$19:$K$34,"-",0,1) -> #REF! | F23: 0
B24: 7 | C24: =+IF(D24="-","","Clase sincrónica de la unidad (3ra) (AF)") -> #REF! | D24: =+_xlfn.XLOOKUP(_xlfn.CONCAT("Unidad ",$A$4,"-",B24),cronograma!#REF!,cronograma!$J$19:$J$34,"-",0,1) -> #REF! | E24: =+_xlfn.XLOOKUP(_xlfn.CONCAT("Unidad ",$A$4,"-",B24),cronograma!#REF!,cronograma!$K$19:$K$34,"-",0,1) -> #REF!
B26: Referencias: AA: Actividad de aprendizaje individual AI: Actividad Interactiva AF: Actividad de Fijación Estas fechas son recomendaciones para ayudar a la organización de tus estudios. Principalmente, debes tener en cuenta las fechas de entrega y los periodos de participación de las actividades. Ante cualquier duda, recuerda que puedes manifestarla en el foro Consultas de esta unidad. Estoy aquí para acompañarte.

Sheet DA1.1
B3: Analítica de Big Data
A4: 1 | B4: =+_xlfn.CONCAT("Unidad ",A4,": ",_xlfn.XLOOKUP(_xlfn.CONCAT("Unidad ",A4),Tabla5[Unidad],Tabla5[Nombre de la unidad],"",0,1)) -> Unidad 1: Manejo de datos en Big Data – Introducciones conceptuales
B5: =+_xlfn.CONCAT("Descripción de la actividad ",A4,".1") -> Descripción de la actividad 1.1
B7: Estimado estudiante, la actividad 1 consiste en estudiar los materiales disponibles en el apartado de Recursos del aula virtual y la actividad 2 consiste en completar una breve actividad de evaluación sobre lo aprendido. Para este trabajo pupedes seguir las indicaciones siguientes: 1. Estudia los contenidos tratados en clase apoyado en los materiales de aprendizaje 2. Visualiza también los videos tutoriales disponibles. 3. Responde y resuelve las cuestiones planteadas en el apartado de la actividad 1 de la unidad dentro del aula virtual 4. El plazo para participar de estas actividades está dado en la tabla
B20: Nro. | C20: Descripción de Actividad | D20: Inicio | E20: Fin | F20: Puntos
B21: 1 | C21: Estudio de los materiales de aprendizaje de la unidad (AF) | D21: =+_xlfn.XLOOKUP(_xlfn.CONCAT("Unidad ",$A$4,"-",B21),cronograma!#REF!,cronograma!$J$19:$J$34,"-",0,1) -> #REF! | E21: =+_xlfn.XLOOKUP(_xlfn.CONCAT("Unidad ",$A$4,"-",B21),cronograma!#REF!,cronograma!$K$19:$K$34,"-",0,1) -> #REF! | F21: 0
B23: Referencias: AA: Actividad de aprendizaje individual AI: Actividad Interactiva AF: Actividad de Fijación Ante cualquier duda, recuerda que puedes manifestarla en el foro Consultas de esta unidad. Estoy aquí para acompañarte.

Sheet DA2.1
B3: =GDcronog!B3 -> Analítica de Big Data
A4: 2 | B4: =+_xlfn.CONCAT("Unidad ",A4,": ",_xlfn.XLOOKUP(_xlfn.CONCAT("Unidad ",A4),Tabla5[Unidad],Tabla5[Nombre de la unidad],"",0,1)) -> Unidad 2: Exploración y visualización datos en Big Data
B5: =+_xlfn.CONCAT("Descripción de la actividad ",A4,".1") -> Descripción de la actividad 2.1
B7: Estimado estudiante, la actividad 1 consiste en estudiar los materiales disponibles en el apartado de Recursos del aula virtual y la actividad 2 consiste en completar una breve actividad de evaluación sobre lo aprendido. Para este trabajo pupedes seguir las indicaciones siguientes: 1. Estudia los contenidos tratados en clase apoyado en los materiales de aprendizaje 2. Visualiza también los videos tutoriales disponibles. 3. Responde y resuelve las cuestiones planteadas en el apartado de la actividad 3 de la unidad dentro del aula virtual 4. El plazo para participar de estas actividades está dado en la tabla
B20: Nro. | C20: Descripción de Actividad | D20: Inicio | E20: Fin | F20: Puntos
B21: 1 | C21: Estudio de los materiales de aprendizaje de la unidad (AF) | D21: =+_xlfn.XLOOKUP(_xlfn.CONCAT("Unidad ",$A$4,"-",B21),cronograma!#REF!,cronograma!$J$19:$J$34,"-",0,1) -> #REF! | E21: =+_xlfn.XLOOKUP(_xlfn.CONCAT("Unidad ",$A$4,"-",B21),cronograma!#REF!,cronograma!$K$19:$K$34,"-",0,1) -> #REF! | F21: 0
B23: Referencias: AA: Actividad de aprendizaje individual AI: Actividad Interactiva AF: Actividad de Fijación Ante cualquier duda, recuerda que puedes manifestarla en el foro Consultas de esta unidad. Estoy aquí para acompañarte.

Sheet DA3.1
B3: =GDcronog!B3 -> Analítica de Big Data
A4: 3 | B4: =+_xlfn.CONCAT("Unidad ",A4,": ",_xlfn.XLOOKUP(_xlfn.CONCAT("Unidad ",A4),Tabla5[Unidad],Tabla5[Nombre de la unidad],"",0,1)) -> Unidad 3: Machine Learning para Big Data
B5: =+_xlfn.CONCAT("Descripción de la actividad ",A4,".1") -> Descripción de la actividad 3.1
B7: Estimado estudiante, la actividad 1 consiste en estudiar los materiales disponibles en el apartado de Recursos del aula virtual y la actividad 2 consiste en completar una breve actividad de evaluación sobre lo aprendido. Para este trabajo pupedes seguir las indicaciones siguientes: 1. Estudia los contenidos tratados en clase apoyado en los materiales de aprendizaje 2. Visualiza también los videos tutoriales disponibles. 3. Responde y resuelve las cuestiones planteadas en el apartado de la actividad 3 de la unidad dentro del aula virtual 4. El plazo para participar de estas actividades está dado en la tabla
B20: Nro. | C20: Descripción de Actividad | D20: Inicio | E20: Fin | F20: Puntos
B21: 1 | C21: Estudio de los materiales de aprendizaje de la unidad (AF) | D21: =+_xlfn.XLOOKUP(_xlfn.CONCAT("Unidad ",$A$4,"-",B21),cronograma!#REF!,cronograma!$J$19:$J$34,"-",0,1) -> #REF! | E21: =+_xlfn.XLOOKUP(_xlfn.CONCAT("Unidad ",$A$4,"-",B21),cronograma!#REF!,cronograma!$K$19:$K$34,"-",0,1) -> #REF! | F21: 0
B23: Referencias: AA: Actividad de aprendizaje individual AI: Actividad Interactiva AF: Actividad de Fijación Ante cualquier duda, recuerda que puedes manifestarla en el foro Consultas de esta unidad. Estoy aquí para acompañarte.

Sheet DA4.1
B3: =GDcronog!B3 -> Analítica de Big Data
A4: 4 | B4: =+_xlfn.CONCAT("Unidad ",A4,": ",_xlfn.XLOOKUP(_xlfn.CONCAT("Unidad ",A4),Tabla5[Unidad],Tabla5[Nombre de la unidad],"",0,1)) -> Unidad 4: Interpretación de los resultados y modelos estadísticos en Big Data
B5: =+_xlfn.CONCAT("Descripción de la actividad ",A4,".1") -> Descripción de la actividad 4.1
B7: Estimado estudiante, la actividad 1 consiste en estudiar los materiales disponibles en el apartado de Recursos del aula virtual y la actividad 2 consiste en completar una breve actividad de evaluación sobre lo aprendido. Para este trabajo pupedes seguir las indicaciones siguientes: 1. Estudia los contenidos tratados en clase apoyado en los materiales de aprendizaje 2. Visualiza también los videos tutoriales disponibles. 3. Responde y resuelve las cuestiones planteadas en el apartado de la actividad 3 de la unidad dentro del aula virtual 4. El plazo para participar de estas actividades está dado en la tabla
B20: Nro. | C20: Descripción de Actividad | D20: Inicio | E20: Fin | F20: Puntos
B21: 1 | C21: Estudio de los materiales de aprendizaje de la unidad (AF) | D21: =+_xlfn.XLOOKUP(_xlfn.CONCAT("Unidad ",$A$4,"-",B21),cronograma!#REF!,cronograma!$J$19:$J$34,"-",0,1) -> #REF! | E21: =+_xlfn.XLOOKUP(_xlfn.CONCAT("Unidad ",$A$4,"-",B21),cronograma!#REF!,cronograma!$K$19:$K$34,"-",0,1) -> #REF! | F21: 0
B23: Referencias: AA: Actividad de aprendizaje individual AI: Actividad Interactiva AF: Actividad de Fijación Ante cualquier duda, recuerda que puedes manifestarla en el foro Consultas de esta unidad. Estoy aquí para acompañarte.

Sheet DA1.2
B3: Control de Proyectos
A4: 1 | B4: =+_xlfn.CONCAT("Unidad ",A4,": ",_xlfn.XLOOKUP(_xlfn.CONCAT("Unidad ",A4),Tabla5[Unidad],Tabla5[Nombre de la unidad],"",0,1)) -> Unidad 1: Manejo de datos en Big Data – Introducciones conceptuales
B5: =+_xlfn.CONCAT("Descripción de las actividades ",A4,".2") -> Descripción de las actividades 1.2
B7: Estimado estudiante, esta actividad consiste en participar del foro sobre los problemas de aplicación de la unidad. Para este trabajo debes seguir las indicaciones siguientes: 1. Lee con detenimiento el material de lectura de la unidad que encontrarás en el apartado “Recursos”. 2. Visualiza también los videos disponibles. 3. Accede al enlace del documento compartido indicado en la descripción del foro 4. Selecciona una de las hojas con los ejercicios planteados (no debe coincidir con la de otro compañero). 5. Las respuestas y los comentarios los pueden dejar en la misma hoja del Excel. 6. Simplemente seleccionan la celda con el contenido que desean comentar y, 7. con el botón derecho despliegan las opciones y seleccionan "Comentario". 8. Responde a las cuestiones planteadas resolviendo la consigna en la hoja del Excel. 9. Recuerda que no debes descargar el libro sino editarlo en línea. 10. Lee cada día los aportes que van danto tus compañeros y compañeras. 11. Realiza un comentario al menos a dos de los aportes dados por tus compañeros. 12. Añade al foro un nuevo tema indicando cuál de los problemas seleccionaste para resolver. 13. El plazo para participar de esta actividad está dado en la tabla
B25: Nro. | C25: Descripción de Actividad | E25: Inicio | F25: Fin | G25: Puntos
B26: 2 | C26: Foro de discusión sobre problemas de aplicación (AI) | E26: =+_xlfn.XLOOKUP(_xlfn.CONCAT("Unidad ",$A$4,"-",B26),cronograma!#REF!,cronograma!$J$19:$J$34,"-",0,1) -> #REF! | F26: =+_xlfn.XLOOKUP(_xlfn.CONCAT("Unidad ",$A$4,"-",B26),cronograma!#REF!,cronograma!$K$19:$K$34,"-",0,1) -> #REF! | G26: 100
B28: Referencias: AA: Actividad de aprendizaje individual AI: Actividad Interactiva AF: Actividad de Fijación
